File: SampleData/LabXRayData/111 run 1 repeated scan_1 PZT56_44.xrdml
<?xml version="1.0" encoding="UTF-8"?>
<xrdMeasurements xmlns="http://www.xrdml.com/XRDMeasurement/1.5" xmlns:xsi="http://www.w3.org/2001/XMLSchema-instance" xsi:schemaLocation="http://www.xrdml.com/XRDMeasurement/1.5 http://www.xrdml.com/XRDMeasurement/1.5/XRDMeasurement.xsd" status="Aborted">
	<comment>
		<entry>Configuration=XRK900 "Ramp", Owner=User-1, Creation date=3/7/2016 4:24:54 PM</entry>
		<entry>Goniometer=Theta/Theta; Minimum step size 2Theta:0.0001; Minimum step size Omega:0.0001</entry>
		<entry>Sample stage=AP XRK-900 with z-axis; Minimum step size Z:0.001</entry>
		<entry>Diffractometer system=EMPYREAN</entry>
		<entry>Measurement program=C:\PANalytical\Data Collector\Programs\Richard\E field measurement\XRK-111 repeated scan.xrdmp, Identifier={7D951DBC-01DB-439D-97B1-E47086035B6A}</entry>
	</comment>
	<sample type="To be analyzed">
		<id></id>
		<name></name>
		<preparedBy></preparedBy>
	</sample>
	<xrdMeasurement measurementType="Repeated scan" status="Aborted" sampleMode="Reflection">
		<comment>
			<entry/>
		</comment>
		<usedWavelength intended="K-Alpha">
			<kAlpha1 unit="Angstrom">1.5405980</kAlpha1>
			<kAlpha2 unit="Angstrom">1.5444260</kAlpha2>
			<kBeta unit="Angstrom">1.3922500</kBeta>
			<ratioKAlpha2KAlpha1>0.5000</ratioKAlpha2KAlpha1>
		</usedWavelength>
		<incidentBeamPath>
			<radius unit="mm">240.00</radius>
			<xRayTube id="1010041" name="Empyrean Cu LFF (9430 033 7300x) DK303567">
				<tension unit="kV">45</tension>
				<current unit="mA">40</current>
				<anodeMaterial>Cu</anodeMaterial>
				<focus type="Line">
					<length unit="mm">12.0</length>
					<width unit="mm">0.4</width>
					<takeOffAngle unit="deg">6.0</takeOffAngle>
				</focus>
			</xRayTube>
			<sollerSlit id="21010002" name="Soller slits 0.04 rad.">
				<opening unit="rad">0.0400</opening>
			</sollerSlit>
			<mask id="22080002" name="Fixed incident beam mask 10 mm">
				<width unit="mm">6.60</width>
			</mask>
			<antiScatterSlit id="22010004" name="Fixed slit 1/2Â°" xsi:type="fixedAntiScatterSlitType">
				<height unit="mm">0.76</height>
			</antiScatterSlit>
			<divergenceSlit id="22010012" name="Programmable divergence slit" xsi:type="fixedDivergenceSlitType">
				<distanceToSample unit="mm">140.00</distanceToSample>
				<angle unit="deg">0.25</angle>
			</divergenceSlit>
		</incidentBeamPath>
		<sampleOffset>
			<position axis="Omega" unit="deg">-0.5952</position>
		</sampleOffset>
		<diffractedBeamPath>
			<radius unit="mm">240.00</radius>
			<antiScatterSlit id="22060009" name="Programmable anti-scatter slit" xsi:type="fixedAntiScatterSlitType">
				<angle unit="deg">0.25</angle>
			</antiScatterSlit>
			<sollerSlit id="21010002" name="Soller slits 0.04 rad.">
				<opening unit="rad">0.0400</opening>
			</sollerSlit>
			<monochromator id="23010033" name="Diffracted beam monochr. for PIXcel and Cu" hybrid="false">
				<crystal type="Symmetric" shape="Flat">C</crystal>
				<numberOfReflections>1</numberOfReflections>
				<hkl>
					<h>0</h>
					<k>0</k>
					<l>2</l>
				</hkl>
			</monochromator>
			<detector id="7010015" name="PIXcel1D detector" xsi:type="rtmsDetectorType">
				<phd>
					<lowerLevel unit="%">25.0</lowerLevel>
					<upperLevel unit="%">100.0</upperLevel>
				</phd>
				<mode>Static</mode>
				<activeLength unit="deg">3.3473</activeLength>
			</detector>
		</diffractedBeamPath>
		<scan appendNumber="0" mode="Continuous" scanAxis="2Theta" status="Completed">
			<header>
				<startTimeStamp>2017-01-10T13:54:33-05:00</startTimeStamp>
				<endTimeStamp>2017-01-10T13:54:57-05:00</endTimeStamp>
				<author>
					<name>NCSU-XRD</name>
				</author>
				<source>
					<applicationSoftware version="4.2">Data Collector</applicationSoftware>
					<instrumentControlSoftware version="7.6  20140701">EMPYREAN</instrumentControlSoftware>
					<instrumentID>0000000011140639</instrumentID>
				</source>
			</header>
			<dataPoints>
				<positions axis="2Theta" unit="deg">
					<listPositions>36.70652469 36.71964394 36.73276337 36.74588298 36.75900275 36.77212269 36.78524281 36.79836308 36.81148353 36.82460413 36.83772490 36.85084583 36.86396692 36.87708817 36.89020958 36.90333114 36.91645285 36.92957472 36.94269674 36.95581891 36.96894123 36.98206370 36.99518631 37.00830906 37.02143196 37.03455501 37.04767819 37.06080151 37.07392497 37.08704857 37.10017230 37.11329616 37.12642016 37.13954428 37.15266854 37.16579293 37.17891744 37.19204208 37.20516684 37.21829172 37.23141673 37.24454185 37.25766710 37.27079246 37.28391793 37.29704352 37.31016923 37.32329504 37.33642097 37.34954700 37.36267315 37.37579940 37.38892575 37.40205220 37.41517876 37.42830542 37.44143218 37.45455904 37.46768599 37.48081304 37.49394018 37.50706741 37.52019474 37.53332215 37.54644966 37.55957724 37.57270492 37.58583268 37.59896052 37.61208844 37.62521645 37.63834453 37.65147269 37.66460092 37.67772923 37.69085761 37.70398607 37.71711459 37.73024319 37.74337185 37.75650057 37.76962937 37.78275822 37.79588714 37.80901612 37.82214515 37.83527425 37.84840340 37.86153261 37.87466187 37.88779118 37.90092055 37.91404996 37.92717942 37.94030893 37.95343848 37.96656808 37.97969772 37.99282741 38.00595713 38.01908689 38.03221669 38.04534652 38.05847639 38.07160629 38.08473623 38.09786619 38.11099618 38.12412620 38.13725625 38.15038632 38.16351642 38.17664653 38.18977667 38.20290683 38.21603700 38.22916720 38.24229740 38.25542762 38.26855786 38.28168810 38.29481835 38.30794862 38.32107888 38.33420916 38.34733944 38.36046972 38.37360000 38.38673028 38.39986056 38.41299084 38.42612112 38.43925138 38.45238165 38.46551190 38.47864214 38.49177238 38.50490260 38.51803280 38.53116300 38.54429317 38.55742333 38.57055347 38.58368358 38.59681368 38.60994375 38.62307380 38.63620382 38.64933381 38.66246377 38.67559371 38.68872361 38.70185348 38.71498331 38.72811311 38.74124287 38.75437259 38.76750228 38.78063192 38.79376152 38.80689107 38.82002058 38.83315004 38.84627945 38.85940882 38.87253813 38.88566739 38.89879660 38.91192575 38.92505485 38.93818388 38.95131286 38.96444178 38.97757063 38.99069943 39.00382815 39.01695681 39.03008541 39.04321393 39.05634239 39.06947077 39.08259908 39.09572731 39.10885547 39.12198355 39.13511156 39.14823948 39.16136732 39.17449508 39.18762276 39.20075034 39.21387785 39.22700526 39.24013259 39.25325982 39.26638696 39.27951401 39.29264096 39.30576782 39.31889458 39.33202124 39.34514780 39.35827425 39.37140060 39.38452685 39.39765300 39.41077903 39.42390496 39.43703077 39.45015648 39.46328207 39.47640754 39.48953290 39.50265815 39.51578327 39.52890828 39.54203316 39.55515792 39.56828256 39.58140707 39.59453146 39.60765572 39.62077984 39.63390384 39.64702770 39.66015143 39.67327503 39.68639849 39.69952181 39.71264499 39.72576804 39.73889094 39.75201369 39.76513630 39.77825877 39.79138109 39.80450326 39.81762528 39.83074715 39.84386886 39.85699042 39.87011183 39.88323308 39.89635417 39.90947510 39.92259587 39.93571647 39.94883692 39.96195719 39.97507731 39.98819725 40.00131702 40.01443663 40.02755606 40.04067531</listPositions>
				</positions>
				<positions axis="Omega" unit="deg">
					<commonPosition>19.1000</commonPosition>
				</positions>
				<positions axis="Z" unit="mm">
					<commonPosition>4.759</commonPosition>
				</positions>
				<commonCountingTime unit="seconds">16.946</commonCountingTime>
				<intensities unit="counts">132 115 148 163 182 180 225 212 206 215 232 260 271 281 275 282 324 305 306 299 311 276 306 309 294 311 312 315 339 303 282 296 302 277 306 333 315 310 294 332 324 270 287 282 315 316 289 277 339 294 305 305 314 346 294 327 320 286 328 336 290 328 304 294 310 341 333 286 322 331 320 314 298 329 348 323 308 319 309 300 351 329 368 352 356 327 387 381 405 465 431 447 438 527 513 530 498 548 523 582 614 629 604 644 648 655 651 728 693 755 813 789 920 1003 1033 1080 1047 1048 1106 1108 1096 1055 1018 932 932 871 774 695 676 591 569 540 469 447 453 416 417 387 407 354 397 374 355 350 346 332 351 351 376 330 330 312 359 307 355 283 316 326 329 270 332 277 324 295 318 299 313 285 307 289 305 324 293 304 295 302 287 296 321 303 261 299 270 292 306 274 277 297 281 311 302 310 305 270 270 287 280 314 292 320 310 281 290 302 295 276 296 322 322 268 283 262 285 300 281 271 268 280 261 284 314 292 269 268 267 295 282 272 255 260 281 254 232 258 255 263 238 247 268 217 261 226 184 203 200 228 230 225 191 188 177 186 193 180 174</intensities>
			</dataPoints>
			<nonAmbientPoints type="Temperature" unit="K">
				<measurementTimes unit="seconds">0</measurementTimes>
				<nonAmbientValues>294</nonAmbientValues>
			</nonAmbientPoints>
		</scan>
		<scan appendNumber="0" mode="Continuous" scanAxis="2Theta" status="Completed">
			<header>
				<startTimeStamp>2017-01-10T13:54:58-05:00</startTimeStamp>
				<endTimeStamp>2017-01-10T13:55:22-05:00</endTimeStamp>
				<author>
					<name>NCSU-XRD</name>
				</author>
				<source>
					<applicationSoftware version="4.2">Data Collector</applicationSoftware>
					<instrumentControlSoftware version="7.6  20140701">EMPYREAN</instrumentControlSoftware>
					<instrumentID>0000000011140639</instrumentID>
				</source>
			</header>
			<dataPoints>
				<positions axis="2Theta" unit="deg">
					<listPositions>36.70652469 36.71964394 36.73276337 36.74588298 36.75900275 36.77212269 36.78524281 36.79836308 36.81148353 36.82460413 36.83772490 36.85084583 36.86396692 36.87708817 36.89020958 36.90333114 36.91645285 36.92957472 36.94269674 36.95581891 36.96894123 36.98206370 36.99518631 37.00830906 37.02143196 37.03455501 37.04767819 37.06080151 37.07392497 37.08704857 37.10017230 37.11329616 37.12642016 37.13954428 37.15266854 37.16579293 37.17891744 37.19204208 37.20516684 37.21829172 37.23141673 37.24454185 37.25766710 37.27079246 37.28391793 37.29704352 37.31016923 37.32329504 37.33642097 37.34954700 37.36267315 37.37579940 37.38892575 37.40205220 37.41517876 37.42830542 37.44143218 37.45455904 37.46768599 37.48081304 37.49394018 37.50706741 37.52019474 37.53332215 37.54644966 37.55957724 37.57270492 37.58583268 37.59896052 37.61208844 37.62521645 37.63834453 37.65147269 37.66460092 37.67772923 37.69085761 37.70398607 37.71711459 37.73024319 37.74337185 37.75650057 37.76962937 37.78275822 37.79588714 37.80901612 37.82214515 37.83527425 37.84840340 37.86153261 37.87466187 37.88779118 37.90092055 37.91404996 37.92717942 37.94030893 37.95343848 37.96656808 37.97969772 37.99282741 38.00595713 38.01908689 38.03221669 38.04534652 38.05847639 38.07160629 38.08473623 38.09786619 38.11099618 38.12412620 38.13725625 38.15038632 38.16351642 38.17664653 38.18977667 38.20290683 38.21603700 38.22916720 38.24229740 38.25542762 38.26855786 38.28168810 38.29481835 38.30794862 38.32107888 38.33420916 38.34733944 38.36046972 38.37360000 38.38673028 38.39986056 38.41299084 38.42612112 38.43925138 38.45238165 38.46551190 38.47864214 38.49177238 38.50490260 38.51803280 38.53116300 38.54429317 38.55742333 38.57055347 38.58368358 38.59681368 38.60994375 38.62307380 38.63620382 38.64933381 38.66246377 38.67559371 38.68872361 38.70185348 38.71498331 38.72811311 38.74124287 38.75437259 38.76750228 38.78063192 38.79376152 38.80689107 38.82002058 38.83315004 38.84627945 38.85940882 38.87253813 38.88566739 38.89879660 38.91192575 38.92505485 38.93818388 38.95131286 38.96444178 38.97757063 38.99069943 39.00382815 39.01695681 39.03008541 39.04321393 39.05634239 39.06947077 39.08259908 39.09572731 39.10885547 39.12198355 39.13511156 39.14823948 39.16136732 39.17449508 39.18762276 39.20075034 39.21387785 39.22700526 39.24013259 39.25325982 39.26638696 39.27951401 39.29264096 39.30576782 39.31889458 39.33202124 39.34514780 39.35827425 39.37140060 39.38452685 39.39765300 39.41077903 39.42390496 39.43703077 39.45015648 39.46328207 39.47640754 39.48953290 39.50265815 39.51578327 39.52890828 39.54203316 39.55515792 39.56828256 39.58140707 39.59453146 39.60765572 39.62077984 39.63390384 39.64702770 39.66015143 39.67327503 39.68639849 39.69952181 39.71264499 39.72576804 39.73889094 39.75201369 39.76513630 39.77825877 39.79138109 39.80450326 39.81762528 39.83074715 39.84386886 39.85699042 39.87011183 39.88323308 39.89635417 39.90947510 39.92259587 39.93571647 39.94883692 39.96195719 39.97507731 39.98819725 40.00131702 40.01443663 40.02755606 40.04067531</listPositions>
				</positions>
				<positions axis="Omega" unit="deg">
					<commonPosition>19.1000</commonPosition>
				</positions>
				<positions axis="Z" unit="mm">
					<commonPosition>4.759</commonPosition>
				</positions>
				<commonCountingTime unit="seconds">16.946</commonCountingTime>
				<intensities unit="counts">125 116 144 170 153 193 187 208 203 217 231 259 257 340 313 292 314 270 319 290 309 304 293 321 298 307 295 302 308 314 266 264 322 310 339 295 287 307 334 272 307 335 309 306 294 294 287 324 295 324 324 302 318 314 331 295 304 305 325 311 316 341 309 306 340 307 300 295 323 325 329 359 315 295 318 323 276 360 357 338 326 315 350 320 345 366 397 399 369 423 434 468 498 523 500 515 545 574 574 601 583 616 620 605 641 654 676 639 726 704 801 849 871 935 1019 1017 1087 1078 1125 1115 1063 1033 1051 1015 881 812 714 710 616 631 578 515 471 481 434 429 432 388 353 386 394 369 367 362 329 301 343 360 356 357 308 296 334 319 336 304 294 341 318 312 284 273 303 296 283 299 280 325 318 272 295 280 326 314 337 301 275 302 317 309 319 276 282 284 298 301 286 284 281 287 292 283 262 303 298 274 301 263 317 286 321 276 256 292 316 295 285 275 263 297 291 303 307 308 296 330 277 264 293 291 275 274 266 307 266 300 268 301 283 269 256 303 268 251 272 261 247 252 231 247 227 257 238 233 225 210 211 203 218 175 194 197 180 163 144</intensities>
			</dataPoints>
			<nonAmbientPoints type="Temperature" unit="K">
				<measurementTimes unit="seconds">0</measurementTimes>
				<nonAmbientValues>294</nonAmbientValues>
			</nonAmbientPoints>
		</scan>
		<scan appendNumber="0" mode="Continuous" scanAxis="2Theta" status="Completed">
			<header>
				<startTimeStamp>2017-01-10T13:55:23-05:00</startTimeStamp>
				<endTimeStamp>2017-01-10T13:55:47-05:00</endTimeStamp>
				<author>
					<name>NCSU-XRD</name>
				</author>
				<source>
					<applicationSoftware version="4.2">Data Collector</applicationSoftware>
					<instrumentControlSoftware version="7.6  20140701">EMPYREAN</instrumentControlSoftware>
					<instrumentID>0000000011140639</instrumentID>
				</source>
			</header>
			<dataPoints>
				<positions axis="2Theta" unit="deg">
					<listPositions>36.70652469 36.71964394 36.73276337 36.74588298 36.75900275 36.77212269 36.78524281 36.79836308 36.81148353 36.82460413 36.83772490 36.85084583 36.86396692 36.87708817 36.89020958 36.90333114 36.91645285 36.92957472 36.94269674 36.95581891 36.96894123 36.98206370 36.99518631 37.00830906 37.02143196 37.03455501 37.04767819 37.06080151 37.07392497 37.08704857 37.10017230 37.11329616 37.12642016 37.13954428 37.15266854 37.16579293 37.17891744 37.19204208 37.20516684 37.21829172 37.23141673 37.24454185 37.25766710 37.27079246 37.28391793 37.29704352 37.31016923 37.32329504 37.33642097 37.34954700 37.36267315 37.37579940 37.38892575 37.40205220 37.41517876 37.42830542 37.44143218 37.45455904 37.46768599 37.48081304 37.49394018 37.50706741 37.52019474 37.53332215 37.54644966 37.55957724 37.57270492 37.58583268 37.59896052 37.61208844 37.62521645 37.63834453 37.65147269 37.66460092 37.67772923 37.69085761 37.70398607 37.71711459 37.73024319 37.74337185 37.75650057 37.76962937 37.78275822 37.79588714 37.80901612 37.82214515 37.83527425 37.84840340 37.86153261 37.87466187 37.88779118 37.90092055 37.91404996 37.92717942 37.94030893 37.95343848 37.96656808 37.97969772 37.99282741 38.00595713 38.01908689 38.03221669 38.04534652 38.05847639 38.07160629 38.08473623 38.09786619 38.11099618 38.12412620 38.13725625 38.15038632 38.16351642 38.17664653 38.18977667 38.20290683 38.21603700 38.22916720 38.24229740 38.25542762 38.26855786 38.28168810 38.29481835 38.30794862 38.32107888 38.33420916 38.34733944 38.36046972 38.37360000 38.38673028 38.39986056 38.41299084 38.42612112 38.43925138 38.45238165 38.46551190 38.47864214 38.49177238 38.50490260 38.51803280 38.53116300 38.54429317 38.55742333 38.57055347 38.58368358 38.59681368 38.60994375 38.62307380 38.63620382 38.64933381 38.66246377 38.67559371 38.68872361 38.70185348 38.71498331 38.72811311 38.74124287 38.75437259 38.76750228 38.78063192 38.79376152 38.80689107 38.82002058 38.83315004 38.84627945 38.85940882 38.87253813 38.88566739 38.89879660 38.91192575 38.92505485 38.93818388 38.95131286 38.96444178 38.97757063 38.99069943 39.00382815 39.01695681 39.03008541 39.04321393 39.05634239 39.06947077 39.08259908 39.09572731 39.10885547 39.12198355 39.13511156 39.14823948 39.16136732 39.17449508 39.18762276 39.20075034 39.21387785 39.22700526 39.24013259 39.25325982 39.26638696 39.27951401 39.29264096 39.30576782 39.31889458 39.33202124 39.34514780 39.35827425 39.37140060 39.38452685 39.39765300 39.41077903 39.42390496 39.43703077 39.45015648 39.46328207 39.47640754 39.48953290 39.50265815 39.51578327 39.52890828 39.54203316 39.55515792 39.56828256 39.58140707 39.59453146 39.60765572 39.62077984 39.63390384 39.64702770 39.66015143 39.67327503 39.68639849 39.69952181 39.71264499 39.72576804 39.73889094 39.75201369 39.76513630 39.77825877 39.79138109 39.80450326 39.81762528 39.83074715 39.84386886 39.85699042 39.87011183 39.88323308 39.89635417 39.90947510 39.92259587 39.93571647 39.94883692 39.96195719 39.97507731 39.98819725 40.00131702 40.01443663 40.02755606 40.04067531</listPositions>
				</positions>
				<positions axis="Omega" unit="deg">
					<commonPosition>19.1000</commonPosition>
				</positions>
				<positions axis="Z" unit="mm">
					<commonPosition>4.759</commonPosition>
				</positions>
				<commonCountingTime unit="seconds">16.946</commonCountingTime>
				<intensities unit="counts">124 156 150 162 139 182 189 225 216 221 260 256 275 293 307 300 259 268 320 267 285 287 302 299 303 297 298 288 301 319 309 291 342 307 316 333 294 296 319 314 303 325 316 289 310 288 300 306 282 283 287 294 277 293 304 340 310 303 299 320 285 324 339 303 316 320 316 342 318 338 353 302 326 320 366 284 351 323 328 346 326 322 342 316 331 343 366 388 398 385 428 444 476 498 516 576 553 546 619 557 616 643 606 621 670 607 672 716 736 741 796 872 924 974 1039 1022 1084 1058 1108 1130 1132 1069 972 961 899 843 770 701 660 586 565 560 493 451 418 421 400 385 383 369 339 371 326 336 331 339 314 319 360 313 307 354 343 319 325 309 337 302 311 296 314 302 328 293 302 303 355 317 327 312 346 298 319 318 290 263 279 283 262 312 291 296 273 280 281 278 272 327 307 286 273 270 284 295 325 285 301 308 347 248 280 289 293 288 272 268 310 274 317 264 302 261 290 286 281 283 307 277 300 299 280 325 238 266 264 281 279 292 299 241 283 283 246 276 254 277 253 272 249 266 244 224 231 217 201 193 235 228 202 187 193 197 190 176 159</intensities>
			</dataPoints>
			<nonAmbientPoints type="Temperature" unit="K">
				<measurementTimes unit="seconds">0</measurementTimes>
				<nonAmbientValues>294</nonAmbientValues>
			</nonAmbientPoints>
		</scan>
		<scan appendNumber="0" mode="Continuous" scanAxis="2Theta" status="Completed">
			<header>
				<startTimeStamp>2017-01-10T13:55:49-05:00</startTimeStamp>
				<endTimeStamp>2017-01-10T13:56:13-05:00</endTimeStamp>
				<author>
					<name>NCSU-XRD</name>
				</author>
				<source>
					<applicationSoftware version="4.2">Data Collector</applicationSoftware>
					<instrumentControlSoftware version="7.6  20140701">EMPYREAN</instrumentControlSoftware>
					<instrumentID>0000000011140639</instrumentID>
				</source>
			</header>
			<dataPoints>
				<positions axis="2Theta" unit="deg">
					<listPositions>36.70652469 36.71964394 36.73276337 36.74588298 36.75900275 36.77212269 36.78524281 36.79836308 36.81148353 36.82460413 36.83772490 36.85084583 36.86396692 36.87708817 36.89020958 36.90333114 36.91645285 36.92957472 36.94269674 36.95581891 36.96894123 36.98206370 36.99518631 37.00830906 37.02143196 37.03455501 37.04767819 37.06080151 37.07392497 37.08704857 37.10017230 37.11329616 37.12642016 37.13954428 37.15266854 37.16579293 37.17891744 37.19204208 37.20516684 37.21829172 37.23141673 37.24454185 37.25766710 37.27079246 37.28391793 37.29704352 37.31016923 37.32329504 37.33642097 37.34954700 37.36267315 37.37579940 37.38892575 37.40205220 37.41517876 37.42830542 37.44143218 37.45455904 37.46768599 37.48081304 37.49394018 37.50706741 37.52019474 37.53332215 37.54644966 37.55957724 37.57270492 37.58583268 37.59896052 37.61208844 37.62521645 37.63834453 37.65147269 37.66460092 37.67772923 37.69085761 37.70398607 37.71711459 37.73024319 37.74337185 37.75650057 37.76962937 37.78275822 37.79588714 37.80901612 37.82214515 37.83527425 37.84840340 37.86153261 37.87466187 37.88779118 37.90092055 37.91404996 37.92717942 37.94030893 37.95343848 37.96656808 37.97969772 37.99282741 38.00595713 38.01908689 38.03221669 38.04534652 38.05847639 38.07160629 38.08473623 38.09786619 38.11099618 38.12412620 38.13725625 38.15038632 38.16351642 38.17664653 38.18977667 38.20290683 38.21603700 38.22916720 38.24229740 38.25542762 38.26855786 38.28168810 38.29481835 38.30794862 38.32107888 38.33420916 38.34733944 38.36046972 38.37360000 38.38673028 38.39986056 38.41299084 38.42612112 38.43925138 38.45238165 38.46551190 38.47864214 38.49177238 38.50490260 38.51803280 38.53116300 38.54429317 38.55742333 38.57055347 38.58368358 38.59681368 38.60994375 38.62307380 38.63620382 38.64933381 38.66246377 38.67559371 38.68872361 38.70185348 38.71498331 38.72811311 38.74124287 38.75437259 38.76750228 38.78063192 38.79376152 38.80689107 38.82002058 38.83315004 38.84627945 38.85940882 38.87253813 38.88566739 38.89879660 38.91192575 38.92505485 38.93818388 38.95131286 38.96444178 38.97757063 38.99069943 39.00382815 39.01695681 39.03008541 39.04321393 39.05634239 39.06947077 39.08259908 39.09572731 39.10885547 39.12198355 39.13511156 39.14823948 39.16136732 39.17449508 39.18762276 39.20075034 39.21387785 39.22700526 39.24013259 39.25325982 39.26638696 39.27951401 39.29264096 39.30576782 39.31889458 39.33202124 39.34514780 39.35827425 39.37140060 39.38452685 39.39765300 39.41077903 39.42390496 39.43703077 39.45015648 39.46328207 39.47640754 39.48953290 39.50265815 39.51578327 39.52890828 39.54203316 39.55515792 39.56828256 39.58140707 39.59453146 39.60765572 39.62077984 39.63390384 39.64702770 39.66015143 39.67327503 39.68639849 39.69952181 39.71264499 39.72576804 39.73889094 39.75201369 39.76513630 39.77825877 39.79138109 39.80450326 39.81762528 39.83074715 39.84386886 39.85699042 39.87011183 39.88323308 39.89635417 39.90947510 39.92259587 39.93571647 39.94883692 39.96195719 39.97507731 39.98819725 40.00131702 40.01443663 40.02755606 40.04067531</listPositions>
				</positions>
				<positions axis="Omega" unit="deg">
					<commonPosition>19.1000</commonPosition>
				</positions>
				<positions axis="Z" unit="mm">
					<commonPosition>4.759</commonPosition>
				</positions>
				<commonCountingTime unit="seconds">16.946</commonCountingTime>
				<intensities unit="counts">116 130 153 164 154 185 191 224 218 244 231 308 282 278 307 292 308 277 292 336 317 306 288 338 292 332 289 333 277 318 296 317 284 304 337 329 315 348 312 298 325 341 330 331 327 303 292 300 292 328 315 265 300 295 322 308 323 318 330 335 318 324 335 324 303 289 314 307 306 298 346 306 293 310 297 341 318 324 319 328 338 328 346 327 343 379 370 386 430 454 453 502 532 493 563 571 557 568 652 608 654 639 633 636 619 660 656 730 727 766 807 842 922 941 980 1058 1135 1166 1099 1068 1122 1064 968 895 892 868 789 684 622 601 550 524 511 446 446 456 452 393 400 396 393 369 368 305 346 310 361 306 300 358 364 346 319 313 305 356 348 298 327 283 333 303 281 305 304 306 328 307 313 324 290 292 303 300 302 308 304 330 281 310 307 315 300 268 301 297 311 265 250 316 304 293 288 286 312 293 301 294 292 286 332 276 288 307 290 314 260 286 310 294 350 288 294 287 317 293 300 289 252 267 298 276 280 273 297 260 274 255 276 242 273 285 294 274 248 268 255 254 251 224 263 240 226 241 216 225 204 217 176 190 192 181 185 177 164</intensities>
			</dataPoints>
			<nonAmbientPoints type="Temperature" unit="K">
				<measurementTimes unit="seconds">0</measurementTimes>
				<nonAmbientValues>294</nonAmbientValues>
			</nonAmbientPoints>
		</scan>
		<scan appendNumber="0" mode="Continuous" scanAxis="2Theta" status="Completed">
			<header>
				<startTimeStamp>2017-01-10T13:56:14-05:00</startTimeStamp>
				<endTimeStamp>2017-01-10T13:56:38-05:00</endTimeStamp>
				<author>
					<name>NCSU-XRD</name>
				</author>
				<source>
					<applicationSoftware version="4.2">Data Collector</applicationSoftware>
					<instrumentControlSoftware version="7.6  20140701">EMPYREAN</instrumentControlSoftware>
					<instrumentID>0000000011140639</instrumentID>
				</source>
			</header>
			<dataPoints>
				<positions axis="2Theta" unit="deg">
					<listPositions>36.70652469 36.71964394 36.73276337 36.74588298 36.75900275 36.77212269 36.78524281 36.79836308 36.81148353 36.82460413 36.83772490 36.85084583 36.86396692 36.87708817 36.89020958 36.90333114 36.91645285 36.92957472 36.94269674 36.95581891 36.96894123 36.98206370 36.99518631 37.00830906 37.02143196 37.03455501 37.04767819 37.06080151 37.07392497 37.08704857 37.10017230 37.11329616 37.12642016 37.13954428 37.15266854 37.16579293 37.17891744 37.19204208 37.20516684 37.21829172 37.23141673 37.24454185 37.25766710 37.27079246 37.28391793 37.29704352 37.31016923 37.32329504 37.33642097 37.34954700 37.36267315 37.37579940 37.38892575 37.40205220 37.41517876 37.42830542 37.44143218 37.45455904 37.46768599 37.48081304 37.49394018 37.50706741 37.52019474 37.53332215 37.54644966 37.55957724 37.57270492 37.58583268 37.59896052 37.61208844 37.62521645 37.63834453 37.65147269 37.66460092 37.67772923 37.69085761 37.70398607 37.71711459 37.73024319 37.74337185 37.75650057 37.76962937 37.78275822 37.79588714 37.80901612 37.82214515 37.83527425 37.84840340 37.86153261 37.87466187 37.88779118 37.90092055 37.91404996 37.92717942 37.94030893 37.95343848 37.96656808 37.97969772 37.99282741 38.00595713 38.01908689 38.03221669 38.04534652 38.05847639 38.07160629 38.08473623 38.09786619 38.11099618 38.12412620 38.13725625 38.15038632 38.16351642 38.17664653 38.18977667 38.20290683 38.21603700 38.22916720 38.24229740 38.25542762 38.26855786 38.28168810 38.29481835 38.30794862 38.32107888 38.33420916 38.34733944 38.36046972 38.37360000 38.38673028 38.39986056 38.41299084 38.42612112 38.43925138 38.45238165 38.46551190 38.47864214 38.49177238 38.50490260 38.51803280 38.53116300 38.54429317 38.55742333 38.57055347 38.58368358 38.59681368 38.60994375 38.62307380 38.63620382 38.64933381 38.66246377 38.67559371 38.68872361 38.70185348 38.71498331 38.72811311 38.74124287 38.75437259 38.76750228 38.78063192 38.79376152 38.80689107 38.82002058 38.83315004 38.84627945 38.85940882 38.87253813 38.88566739 38.89879660 38.91192575 38.92505485 38.93818388 38.95131286 38.96444178 38.97757063 38.99069943 39.00382815 39.01695681 39.03008541 39.04321393 39.05634239 39.06947077 39.08259908 39.09572731 39.10885547 39.12198355 39.13511156 39.14823948 39.16136732 39.17449508 39.18762276 39.20075034 39.21387785 39.22700526 39.24013259 39.25325982 39.26638696 39.27951401 39.29264096 39.30576782 39.31889458 39.33202124 39.34514780 39.35827425 39.37140060 39.38452685 39.39765300 39.41077903 39.42390496 39.43703077 39.45015648 39.46328207 39.47640754 39.48953290 39.50265815 39.51578327 39.52890828 39.54203316 39.55515792 39.56828256 39.58140707 39.59453146 39.60765572 39.62077984 39.63390384 39.64702770 39.66015143 39.67327503 39.68639849 39.69952181 39.71264499 39.72576804 39.73889094 39.75201369 39.76513630 39.77825877 39.79138109 39.80450326 39.81762528 39.83074715 39.84386886 39.85699042 39.87011183 39.88323308 39.89635417 39.90947510 39.92259587 39.93571647 39.94883692 39.96195719 39.97507731 39.98819725 40.00131702 40.01443663 40.02755606 40.04067531</listPositions>
				</positions>
				<positions axis="Omega" unit="deg">
					<commonPosition>19.1000</commonPosition>
				</positions>
				<positions axis="Z" unit="mm">
					<commonPosition>4.759</commonPosition>
				</positions>
				<commonCountingTime unit="seconds">16.946</commonCountingTime>
				<intensities unit="counts">121 132 132 144 173 173 200 206 211 240 252 253 260 261 292 315 282 309 313 309 288 326 279 332 320 283 300 290 324 286 288 289 322 346 311 294 321 263 297 309 320 290 276 290 279 292 314 313 318 320 324 324 301 318 308 314 324 296 308 277 328 337 310 328 267 324 301 338 321 325 321 327 315 284 329 367 335 321 315 343 327 371 368 374 363 364 418 388 479 442 528 553 582 591 639 686 652 651 648 678 708 686 718 659 693 681 738 680 736 708 762 775 821 938 955 910 939 952 1006 930 1010 953 934 853 762 723 693 668 610 579 539 484 454 442 433 400 365 340 364 395 406 352 340 345 338 336 317 352 310 316 324 298 329 368 314 334 349 342 340 313 296 295 304 337 287 306 302 322 319 297 304 264 318 305 335 293 294 285 308 315 319 303 271 299 305 317 297 285 303 298 272 288 278 300 294 281 332 274 263 316 287 306 304 282 304 288 274 286 276 287 309 299 267 304 284 296 302 306 312 298 250 286 301 283 261 273 285 283 235 274 286 249 260 265 244 286 243 260 256 239 242 208 250 248 265 231 194 201 204 195 201 190 175 153 158</intensities>
			</dataPoints>
			<nonAmbientPoints type="Temperature" unit="K">
				<measurementTimes unit="seconds">0</measurementTimes>
				<nonAmbientValues>294</nonAmbientValues>
			</nonAmbientPoints>
		</scan>
		<scan appendNumber="0" mode="Continuous" scanAxis="2Theta" status="Completed">
			<header>
				<startTimeStamp>2017-01-10T13:56:39-05:00</startTimeStamp>
				<endTimeStamp>2017-01-10T13:57:03-05:00</endTimeStamp>
				<author>
					<name>NCSU-XRD</name>
				</author>
				<source>
					<applicationSoftware version="4.2">Data Collector</applicationSoftware>
					<instrumentControlSoftware version="7.6  20140701">EMPYREAN</instrumentControlSoftware>
					<instrumentID>0000000011140639</instrumentID>
				</source>
			</header>
			<dataPoints>
				<positions axis="2Theta" unit="deg">
					<listPositions>36.70652469 36.71964394 36.73276337 36.74588298 36.75900275 36.77212269 36.78524281 36.79836308 36.81148353 36.82460413 36.83772490 36.85084583 36.86396692 36.87708817 36.89020958 36.90333114 36.91645285 36.92957472 36.94269674 36.95581891 36.96894123 36.98206370 36.99518631 37.00830906 37.02143196 37.03455501 37.04767819 37.06080151 37.07392497 37.08704857 37.10017230 37.11329616 37.12642016 37.13954428 37.15266854 37.16579293 37.17891744 37.19204208 37.20516684 37.21829172 37.23141673 37.24454185 37.25766710 37.27079246 37.28391793 37.29704352 37.31016923 37.32329504 37.33642097 37.34954700 37.36267315 37.37579940 37.38892575 37.40205220 37.41517876 37.42830542 37.44143218 37.45455904 37.46768599 37.48081304 37.49394018 37.50706741 37.52019474 37.53332215 37.54644966 37.55957724 37.57270492 37.58583268 37.59896052 37.61208844 37.62521645 37.63834453 37.65147269 37.66460092 37.67772923 37.69085761 37.70398607 37.71711459 37.73024319 37.74337185 37.75650057 37.76962937 37.78275822 37.79588714 37.80901612 37.82214515 37.83527425 37.84840340 37.86153261 37.87466187 37.88779118 37.90092055 37.91404996 37.92717942 37.94030893 37.95343848 37.96656808 37.97969772 37.99282741 38.00595713 38.01908689 38.03221669 38.04534652 38.05847639 38.07160629 38.08473623 38.09786619 38.11099618 38.12412620 38.13725625 38.15038632 38.16351642 38.17664653 38.18977667 38.20290683 38.21603700 38.22916720 38.24229740 38.25542762 38.26855786 38.28168810 38.29481835 38.30794862 38.32107888 38.33420916 38.34733944 38.36046972 38.37360000 38.38673028 38.39986056 38.41299084 38.42612112 38.43925138 38.45238165 38.46551190 38.47864214 38.49177238 38.50490260 38.51803280 38.53116300 38.54429317 38.55742333 38.57055347 38.58368358 38.59681368 38.60994375 38.62307380 38.63620382 38.64933381 38.66246377 38.67559371 38.68872361 38.70185348 38.71498331 38.72811311 38.74124287 38.75437259 38.76750228 38.78063192 38.79376152 38.80689107 38.82002058 38.83315004 38.84627945 38.85940882 38.87253813 38.88566739 38.89879660 38.91192575 38.92505485 38.93818388 38.95131286 38.96444178 38.97757063 38.99069943 39.00382815 39.01695681 39.03008541 39.04321393 39.05634239 39.06947077 39.08259908 39.09572731 39.10885547 39.12198355 39.13511156 39.14823948 39.16136732 39.17449508 39.18762276 39.20075034 39.21387785 39.22700526 39.24013259 39.25325982 39.26638696 39.27951401 39.29264096 39.30576782 39.31889458 39.33202124 39.34514780 39.35827425 39.37140060 39.38452685 39.39765300 39.41077903 39.42390496 39.43703077 39.45015648 39.46328207 39.47640754 39.48953290 39.50265815 39.51578327 39.52890828 39.54203316 39.55515792 39.56828256 39.58140707 39.59453146 39.60765572 39.62077984 39.63390384 39.64702770 39.66015143 39.67327503 39.68639849 39.69952181 39.71264499 39.72576804 39.73889094 39.75201369 39.76513630 39.77825877 39.79138109 39.80450326 39.81762528 39.83074715 39.84386886 39.85699042 39.87011183 39.88323308 39.89635417 39.90947510 39.92259587 39.93571647 39.94883692 39.96195719 39.97507731 39.98819725 40.00131702 40.01443663 40.02755606 40.04067531</listPositions>
				</positions>
				<positions axis="Omega" unit="deg">
					<commonPosition>19.1000</commonPosition>
				</positions>
				<positions axis="Z" unit="mm">
					<commonPosition>4.759</commonPosition>
				</positions>
				<commonCountingTime unit="seconds">16.946</commonCountingTime>
				<intensities unit="counts">111 124 168 150 171 195 196 209 242 271 249 251 296 282 278 295 293 304 287 291 268 296 284 293 292 313 307 351 324 319 293 282 286 292 289 297 282 288 288 294 295 338 307 310 301 338 316 307 284 323 291 310 318 300 302 310 312 284 328 311 308 338 324 321 303 291 305 322 306 321 294 303 314 307 325 346 300 340 353 341 327 369 359 378 421 394 428 471 485 569 602 671 733 783 885 800 879 841 854 884 853 820 781 773 770 743 724 735 740 756 672 736 734 748 759 729 753 729 733 771 724 705 764 718 712 578 564 572 577 497 510 487 455 454 425 374 390 378 381 392 327 348 358 332 319 339 320 307 323 321 321 299 336 295 275 326 341 333 328 344 353 338 285 290 298 298 303 273 299 297 291 288 276 313 291 285 297 311 322 290 301 265 323 313 316 278 296 271 319 272 292 284 296 277 270 256 282 292 316 332 245 305 286 281 301 306 247 267 277 287 292 292 286 291 303 260 280 260 271 296 287 280 259 259 251 267 286 266 259 288 283 263 259 259 258 244 278 245 237 262 270 240 206 217 241 234 203 214 212 206 199 158 139 172 150</intensities>
			</dataPoints>
			<nonAmbientPoints type="Temperature" unit="K">
				<measurementTimes unit="seconds">0</measurementTimes>
				<nonAmbientValues>294</nonAmbientValues>
			</nonAmbientPoints>
		</scan>
		<scan appendNumber="0" mode="Continuous" scanAxis="2Theta" status="Completed">
			<header>
				<startTimeStamp>2017-01-10T13:57:05-05:00</startTimeStamp>
				<endTimeStamp>2017-01-10T13:57:29-05:00</endTimeStamp>
				<author>
					<name>NCSU-XRD</name>
				</author>
				<source>
					<applicationSoftware version="4.2">Data Collector</applicationSoftware>
					<instrumentControlSoftware version="7.6  20140701">EMPYREAN</instrumentControlSoftware>
					<instrumentID>0000000011140639</instrumentID>
				</source>
			</header>
			<dataPoints>
				<positions axis="2Theta" unit="deg">
					<listPositions>36.70652469 36.71964394 36.73276337 36.74588298 36.75900275 36.77212269 36.78524281 36.79836308 36.81148353 36.82460413 36.83772490 36.85084583 36.86396692 36.87708817 36.89020958 36.90333114 36.91645285 36.92957472 36.94269674 36.95581891 36.96894123 36.98206370 36.99518631 37.00830906 37.02143196 37.03455501 37.04767819 37.06080151 37.07392497 37.08704857 37.10017230 37.11329616 37.12642016 37.13954428 37.15266854 37.16579293 37.17891744 37.19204208 37.20516684 37.21829172 37.23141673 37.24454185 37.25766710 37.27079246 37.28391793 37.29704352 37.31016923 37.32329504 37.33642097 37.34954700 37.36267315 37.37579940 37.38892575 37.40205220 37.41517876 37.42830542 37.44143218 37.45455904 37.46768599 37.48081304 37.49394018 37.50706741 37.52019474 37.53332215 37.54644966 37.55957724 37.57270492 37.58583268 37.59896052 37.61208844 37.62521645 37.63834453 37.65147269 37.66460092 37.67772923 37.69085761 37.70398607 37.71711459 37.73024319 37.74337185 37.75650057 37.76962937 37.78275822 37.79588714 37.80901612 37.82214515 37.83527425 37.84840340 37.86153261 37.87466187 37.88779118 37.90092055 37.91404996 37.92717942 37.94030893 37.95343848 37.96656808 37.97969772 37.99282741 38.00595713 38.01908689 38.03221669 38.04534652 38.05847639 38.07160629 38.08473623 38.09786619 38.11099618 38.12412620 38.13725625 38.15038632 38.16351642 38.17664653 38.18977667 38.20290683 38.21603700 38.22916720 38.24229740 38.25542762 38.26855786 38.28168810 38.29481835 38.30794862 38.32107888 38.33420916 38.34733944 38.36046972 38.37360000 38.38673028 38.39986056 38.41299084 38.42612112 38.43925138 38.45238165 38.46551190 38.47864214 38.49177238 38.50490260 38.51803280 38.53116300 38.54429317 38.55742333 38.57055347 38.58368358 38.59681368 38.60994375 38.62307380 38.63620382 38.64933381 38.66246377 38.67559371 38.68872361 38.70185348 38.71498331 38.72811311 38.74124287 38.75437259 38.76750228 38.78063192 38.79376152 38.80689107 38.82002058 38.83315004 38.84627945 38.85940882 38.87253813 38.88566739 38.89879660 38.91192575 38.92505485 38.93818388 38.95131286 38.96444178 38.97757063 38.99069943 39.00382815 39.01695681 39.03008541 39.04321393 39.05634239 39.06947077 39.08259908 39.09572731 39.10885547 39.12198355 39.13511156 39.14823948 39.16136732 39.17449508 39.18762276 39.20075034 39.21387785 39.22700526 39.24013259 39.25325982 39.26638696 39.27951401 39.29264096 39.30576782 39.31889458 39.33202124 39.34514780 39.35827425 39.37140060 39.38452685 39.39765300 39.41077903 39.42390496 39.43703077 39.45015648 39.46328207 39.47640754 39.48953290 39.50265815 39.51578327 39.52890828 39.54203316 39.55515792 39.56828256 39.58140707 39.59453146 39.60765572 39.62077984 39.63390384 39.64702770 39.66015143 39.67327503 39.68639849 39.69952181 39.71264499 39.72576804 39.73889094 39.75201369 39.76513630 39.77825877 39.79138109 39.80450326 39.81762528 39.83074715 39.84386886 39.85699042 39.87011183 39.88323308 39.89635417 39.90947510 39.92259587 39.93571647 39.94883692 39.96195719 39.97507731 39.98819725 40.00131702 40.01443663 40.02755606 40.04067531</listPositions>
				</positions>
				<positions axis="Omega" unit="deg">
					<commonPosition>19.1000</commonPosition>
				</positions>
				<positions axis="Z" unit="mm">
					<commonPosition>4.759</commonPosition>
				</positions>
				<commonCountingTime unit="seconds">16.946</commonCountingTime>
				<intensities unit="counts">114 129 147 182 179 183 214 202 229 235 262 280 304 262 255 248 295 290 345 295 296 305 293 326 316 296 287 311 276 279 281 291 283 286 326 288 324 291 277 291 286 311 262 288 304 267 296 277 294 311 305 307 322 285 282 312 334 306 316 307 338 312 310 286 335 320 337 312 336 291 327 301 298 346 337 324 361 328 343 371 358 364 351 371 435 429 433 476 510 548 642 705 737 806 837 922 882 882 893 850 872 820 825 825 835 776 700 706 722 700 687 686 735 694 746 723 719 709 677 760 774 640 712 724 640 598 573 578 545 537 496 446 449 475 410 421 395 370 385 345 344 327 339 371 320 367 328 324 336 321 364 321 331 329 327 316 294 318 307 335 307 283 327 322 318 273 296 319 296 279 311 274 317 287 312 290 321 295 311 316 301 299 253 296 281 313 306 317 307 300 282 289 302 308 323 271 313 297 256 288 297 270 293 295 276 281 297 319 318 304 309 279 292 298 267 277 269 300 334 282 255 283 263 296 281 268 253 265 274 283 265 266 264 280 252 284 251 254 265 250 245 218 227 218 216 215 219 231 193 198 171 170 173 166 164</intensities>
			</dataPoints>
			<nonAmbientPoints type="Temperature" unit="K">
				<measurementTimes unit="seconds">0</measurementTimes>
[...]
				</positions>
				<positions axis="Omega" unit="deg">
					<commonPosition>19.1000</commonPosition>
				</positions>
				<positions axis="Z" unit="mm">
					<commonPosition>4.759</commonPosition>
				</positions>
				<commonCountingTime unit="seconds">16.946</commonCountingTime>
				<intensities unit="counts">140 119 159 179 170 175 183 191 184 233 234 271 270 292 269 287 290 291 314 277 311 301 276 289 292 330 311 289 303 287 307 301 311 319 304 320 312 352 317 322 302 274 311 286 302 300 299 313 272 302 308 314 312 310 336 323 329 323 310 335 291 293 352 306 298 286 325 295 303 310 341 324 299 295 308 303 323 313 315 355 379 347 398 379 424 411 449 500 530 617 702 737 803 904 847 906 945 932 911 930 853 847 784 801 736 710 768 778 735 652 741 709 689 750 746 769 761 804 772 783 784 741 717 695 630 654 573 535 545 551 471 482 471 476 385 434 394 386 386 318 330 360 353 357 321 329 344 355 341 279 358 328 306 272 295 353 327 301 299 319 316 315 264 330 313 276 306 324 304 274 332 328 315 337 317 325 291 296 306 303 286 284 272 270 260 288 317 312 336 304 301 304 323 302 314 293 275 296 302 290 293 314 282 267 294 293 255 263 306 276 313 303 292 274 274 256 278 297 303 271 264 258 299 287 312 264 281 277 246 282 277 280 263 290 267 246 260 260 244 257 231 211 228 224 230 187 204 225 209 187 177 181 175 175 149</intensities>
			</dataPoints>
			<nonAmbientPoints type="Temperature" unit="K">
				<measurementTimes unit="seconds">0</measurementTimes>
				<nonAmbientValues>294</nonAmbientValues>
			</nonAmbientPoints>
		</scan>
		<scan appendNumber="0" mode="Continuous" scanAxis="2Theta" status="Completed">
			<header>
				<startTimeStamp>2017-01-10T14:13:36-05:00</startTimeStamp>
				<endTimeStamp>2017-01-10T14:14:00-05:00</endTimeStamp>
				<author>
					<name>NCSU-XRD</name>
				</author>
				<source>
					<applicationSoftware version="4.2">Data Collector</applicationSoftware>
					<instrumentControlSoftware version="7.6  20140701">EMPYREAN</instrumentControlSoftware>
					<instrumentID>0000000011140639</instrumentID>
				</source>
			</header>
			<dataPoints>
				<positions axis="2Theta" unit="deg">
					<listPositions>36.70652469 36.71964394 36.73276337 36.74588298 36.75900275 36.77212269 36.78524281 36.79836308 36.81148353 36.82460413 36.83772490 36.85084583 36.86396692 36.87708817 36.89020958 36.90333114 36.91645285 36.92957472 36.94269674 36.95581891 36.96894123 36.98206370 36.99518631 37.00830906 37.02143196 37.03455501 37.04767819 37.06080151 37.07392497 37.08704857 37.10017230 37.11329616 37.12642016 37.13954428 37.15266854 37.16579293 37.17891744 37.19204208 37.20516684 37.21829172 37.23141673 37.24454185 37.25766710 37.27079246 37.28391793 37.29704352 37.31016923 37.32329504 37.33642097 37.34954700 37.36267315 37.37579940 37.38892575 37.40205220 37.41517876 37.42830542 37.44143218 37.45455904 37.46768599 37.48081304 37.49394018 37.50706741 37.52019474 37.53332215 37.54644966 37.55957724 37.57270492 37.58583268 37.59896052 37.61208844 37.62521645 37.63834453 37.65147269 37.66460092 37.67772923 37.69085761 37.70398607 37.71711459 37.73024319 37.74337185 37.75650057 37.76962937 37.78275822 37.79588714 37.80901612 37.82214515 37.83527425 37.84840340 37.86153261 37.87466187 37.88779118 37.90092055 37.91404996 37.92717942 37.94030893 37.95343848 37.96656808 37.97969772 37.99282741 38.00595713 38.01908689 38.03221669 38.04534652 38.05847639 38.07160629 38.08473623 38.09786619 38.11099618 38.12412620 38.13725625 38.15038632 38.16351642 38.17664653 38.18977667 38.20290683 38.21603700 38.22916720 38.24229740 38.25542762 38.26855786 38.28168810 38.29481835 38.30794862 38.32107888 38.33420916 38.34733944 38.36046972 38.37360000 38.38673028 38.39986056 38.41299084 38.42612112 38.43925138 38.45238165 38.46551190 38.47864214 38.49177238 38.50490260 38.51803280 38.53116300 38.54429317 38.55742333 38.57055347 38.58368358 38.59681368 38.60994375 38.62307380 38.63620382 38.64933381 38.66246377 38.67559371 38.68872361 38.70185348 38.71498331 38.72811311 38.74124287 38.75437259 38.76750228 38.78063192 38.79376152 38.80689107 38.82002058 38.83315004 38.84627945 38.85940882 38.87253813 38.88566739 38.89879660 38.91192575 38.92505485 38.93818388 38.95131286 38.96444178 38.97757063 38.99069943 39.00382815 39.01695681 39.03008541 39.04321393 39.05634239 39.06947077 39.08259908 39.09572731 39.10885547 39.12198355 39.13511156 39.14823948 39.16136732 39.17449508 39.18762276 39.20075034 39.21387785 39.22700526 39.24013259 39.25325982 39.26638696 39.27951401 39.29264096 39.30576782 39.31889458 39.33202124 39.34514780 39.35827425 39.37140060 39.38452685 39.39765300 39.41077903 39.42390496 39.43703077 39.45015648 39.46328207 39.47640754 39.48953290 39.50265815 39.51578327 39.52890828 39.54203316 39.55515792 39.56828256 39.58140707 39.59453146 39.60765572 39.62077984 39.63390384 39.64702770 39.66015143 39.67327503 39.68639849 39.69952181 39.71264499 39.72576804 39.73889094 39.75201369 39.76513630 39.77825877 39.79138109 39.80450326 39.81762528 39.83074715 39.84386886 39.85699042 39.87011183 39.88323308 39.89635417 39.90947510 39.92259587 39.93571647 39.94883692 39.96195719 39.97507731 39.98819725 40.00131702 40.01443663 40.02755606 40.04067531</listPositions>
				</positions>
				<positions axis="Omega" unit="deg">
					<commonPosition>19.1000</commonPosition>
				</positions>
				<positions axis="Z" unit="mm">
					<commonPosition>4.759</commonPosition>
				</positions>
				<commonCountingTime unit="seconds">16.946</commonCountingTime>
				<intensities unit="counts">106 116 151 171 147 178 189 234 226 241 238 245 295 272 289 252 318 316 310 294 322 334 299 313 292 273 307 286 286 269 264 328 297 292 308 301 277 334 316 325 322 297 300 298 336 302 319 325 289 286 294 319 306 295 310 309 327 300 315 312 344 299 323 308 311 332 338 308 300 294 302 325 313 313 360 310 325 338 368 366 362 359 389 405 386 443 471 517 535 585 732 755 798 892 847 871 918 886 842 863 868 929 832 776 769 759 798 763 676 741 713 747 741 757 765 724 779 714 791 731 746 715 725 746 733 668 593 530 523 487 514 508 487 474 439 401 400 398 368 379 378 335 339 313 331 350 376 366 345 365 340 340 349 320 328 300 332 310 295 303 309 314 319 317 310 312 300 310 323 323 347 327 307 277 299 292 286 319 323 291 283 286 317 323 322 272 271 267 267 291 304 277 278 270 302 308 290 288 266 312 310 295 293 255 295 284 304 273 276 318 294 277 321 305 298 285 277 286 318 282 288 267 257 284 284 282 292 266 256 300 271 281 292 291 262 271 257 275 259 261 262 222 233 207 210 191 194 230 192 202 222 181 189 175 161</intensities>
			</dataPoints>
			<nonAmbientPoints type="Temperature" unit="K">
				<measurementTimes unit="seconds">0</measurementTimes>
				<nonAmbientValues>294</nonAmbientValues>
			</nonAmbientPoints>
		</scan>
		<scan appendNumber="0" mode="Continuous" scanAxis="2Theta" status="Completed">
			<header>
				<startTimeStamp>2017-01-10T14:14:02-05:00</startTimeStamp>
				<endTimeStamp>2017-01-10T14:14:26-05:00</endTimeStamp>
				<author>
					<name>NCSU-XRD</name>
				</author>
				<source>
					<applicationSoftware version="4.2">Data Collector</applicationSoftware>
					<instrumentControlSoftware version="7.6  20140701">EMPYREAN</instrumentControlSoftware>
					<instrumentID>0000000011140639</instrumentID>
				</source>
			</header>
			<dataPoints>
				<positions axis="2Theta" unit="deg">
					<listPositions>36.70652469 36.71964394 36.73276337 36.74588298 36.75900275 36.77212269 36.78524281 36.79836308 36.81148353 36.82460413 36.83772490 36.85084583 36.86396692 36.87708817 36.89020958 36.90333114 36.91645285 36.92957472 36.94269674 36.95581891 36.96894123 36.98206370 36.99518631 37.00830906 37.02143196 37.03455501 37.04767819 37.06080151 37.07392497 37.08704857 37.10017230 37.11329616 37.12642016 37.13954428 37.15266854 37.16579293 37.17891744 37.19204208 37.20516684 37.21829172 37.23141673 37.24454185 37.25766710 37.27079246 37.28391793 37.29704352 37.31016923 37.32329504 37.33642097 37.34954700 37.36267315 37.37579940 37.38892575 37.40205220 37.41517876 37.42830542 37.44143218 37.45455904 37.46768599 37.48081304 37.49394018 37.50706741 37.52019474 37.53332215 37.54644966 37.55957724 37.57270492 37.58583268 37.59896052 37.61208844 37.62521645 37.63834453 37.65147269 37.66460092 37.67772923 37.69085761 37.70398607 37.71711459 37.73024319 37.74337185 37.75650057 37.76962937 37.78275822 37.79588714 37.80901612 37.82214515 37.83527425 37.84840340 37.86153261 37.87466187 37.88779118 37.90092055 37.91404996 37.92717942 37.94030893 37.95343848 37.96656808 37.97969772 37.99282741 38.00595713 38.01908689 38.03221669 38.04534652 38.05847639 38.07160629 38.08473623 38.09786619 38.11099618 38.12412620 38.13725625 38.15038632 38.16351642 38.17664653 38.18977667 38.20290683 38.21603700 38.22916720 38.24229740 38.25542762 38.26855786 38.28168810 38.29481835 38.30794862 38.32107888 38.33420916 38.34733944 38.36046972 38.37360000 38.38673028 38.39986056 38.41299084 38.42612112 38.43925138 38.45238165 38.46551190 38.47864214 38.49177238 38.50490260 38.51803280 38.53116300 38.54429317 38.55742333 38.57055347 38.58368358 38.59681368 38.60994375 38.62307380 38.63620382 38.64933381 38.66246377 38.67559371 38.68872361 38.70185348 38.71498331 38.72811311 38.74124287 38.75437259 38.76750228 38.78063192 38.79376152 38.80689107 38.82002058 38.83315004 38.84627945 38.85940882 38.87253813 38.88566739 38.89879660 38.91192575 38.92505485 38.93818388 38.95131286 38.96444178 38.97757063 38.99069943 39.00382815 39.01695681 39.03008541 39.04321393 39.05634239 39.06947077 39.08259908 39.09572731 39.10885547 39.12198355 39.13511156 39.14823948 39.16136732 39.17449508 39.18762276 39.20075034 39.21387785 39.22700526 39.24013259 39.25325982 39.26638696 39.27951401 39.29264096 39.30576782 39.31889458 39.33202124 39.34514780 39.35827425 39.37140060 39.38452685 39.39765300 39.41077903 39.42390496 39.43703077 39.45015648 39.46328207 39.47640754 39.48953290 39.50265815 39.51578327 39.52890828 39.54203316 39.55515792 39.56828256 39.58140707 39.59453146 39.60765572 39.62077984 39.63390384 39.64702770 39.66015143 39.67327503 39.68639849 39.69952181 39.71264499 39.72576804 39.73889094 39.75201369 39.76513630 39.77825877 39.79138109 39.80450326 39.81762528 39.83074715 39.84386886 39.85699042 39.87011183 39.88323308 39.89635417 39.90947510 39.92259587 39.93571647 39.94883692 39.96195719 39.97507731 39.98819725 40.00131702 40.01443663 40.02755606 40.04067531</listPositions>
				</positions>
				<positions axis="Omega" unit="deg">
					<commonPosition>19.1000</commonPosition>
				</positions>
				<positions axis="Z" unit="mm">
					<commonPosition>4.759</commonPosition>
				</positions>
				<commonCountingTime unit="seconds">16.946</commonCountingTime>
				<intensities unit="counts">116 129 162 149 148 162 191 235 237 267 253 266 272 321 325 303 301 307 298 315 333 314 318 316 306 316 303 289 314 303 296 264 298 331 331 333 303 311 326 302 296 303 270 316 284 320 322 340 293 304 343 307 342 291 293 319 336 283 339 322 300 280 316 318 299 313 346 327 325 295 341 361 338 363 360 357 363 364 353 305 407 355 383 411 419 389 441 483 549 636 699 739 769 864 865 912 882 932 878 871 867 860 793 792 736 762 708 717 727 696 747 711 753 726 791 798 807 797 755 731 801 764 767 726 693 638 595 548 534 499 507 464 462 446 436 419 429 395 350 375 340 364 345 338 340 337 337 352 303 320 349 329 347 356 337 316 312 313 314 298 306 332 351 352 317 331 318 315 288 303 310 309 306 253 289 292 301 280 318 296 312 289 294 314 306 302 295 290 326 307 312 297 278 288 295 251 304 272 288 294 287 275 292 281 276 300 326 291 295 286 289 295 311 291 303 298 282 289 292 272 258 260 274 273 287 254 318 302 270 256 259 250 296 278 285 287 294 262 223 266 241 216 219 242 232 197 219 237 200 203 183 190 162 158 144</intensities>
			</dataPoints>
			<nonAmbientPoints type="Temperature" unit="K">
				<measurementTimes unit="seconds">0</measurementTimes>
				<nonAmbientValues>294</nonAmbientValues>
			</nonAmbientPoints>
		</scan>
		<scan appendNumber="0" mode="Continuous" scanAxis="2Theta" status="Completed">
			<header>
				<startTimeStamp>2017-01-10T14:14:27-05:00</startTimeStamp>
				<endTimeStamp>2017-01-10T14:14:51-05:00</endTimeStamp>
				<author>
					<name>NCSU-XRD</name>
				</author>
				<source>
					<applicationSoftware version="4.2">Data Collector</applicationSoftware>
					<instrumentControlSoftware version="7.6  20140701">EMPYREAN</instrumentControlSoftware>
					<instrumentID>0000000011140639</instrumentID>
				</source>
			</header>
			<dataPoints>
				<positions axis="2Theta" unit="deg">
					<listPositions>36.70652469 36.71964394 36.73276337 36.74588298 36.75900275 36.77212269 36.78524281 36.79836308 36.81148353 36.82460413 36.83772490 36.85084583 36.86396692 36.87708817 36.89020958 36.90333114 36.91645285 36.92957472 36.94269674 36.95581891 36.96894123 36.98206370 36.99518631 37.00830906 37.02143196 37.03455501 37.04767819 37.06080151 37.07392497 37.08704857 37.10017230 37.11329616 37.12642016 37.13954428 37.15266854 37.16579293 37.17891744 37.19204208 37.20516684 37.21829172 37.23141673 37.24454185 37.25766710 37.27079246 37.28391793 37.29704352 37.31016923 37.32329504 37.33642097 37.34954700 37.36267315 37.37579940 37.38892575 37.40205220 37.41517876 37.42830542 37.44143218 37.45455904 37.46768599 37.48081304 37.49394018 37.50706741 37.52019474 37.53332215 37.54644966 37.55957724 37.57270492 37.58583268 37.59896052 37.61208844 37.62521645 37.63834453 37.65147269 37.66460092 37.67772923 37.69085761 37.70398607 37.71711459 37.73024319 37.74337185 37.75650057 37.76962937 37.78275822 37.79588714 37.80901612 37.82214515 37.83527425 37.84840340 37.86153261 37.87466187 37.88779118 37.90092055 37.91404996 37.92717942 37.94030893 37.95343848 37.96656808 37.97969772 37.99282741 38.00595713 38.01908689 38.03221669 38.04534652 38.05847639 38.07160629 38.08473623 38.09786619 38.11099618 38.12412620 38.13725625 38.15038632 38.16351642 38.17664653 38.18977667 38.20290683 38.21603700 38.22916720 38.24229740 38.25542762 38.26855786 38.28168810 38.29481835 38.30794862 38.32107888 38.33420916 38.34733944 38.36046972 38.37360000 38.38673028 38.39986056 38.41299084 38.42612112 38.43925138 38.45238165 38.46551190 38.47864214 38.49177238 38.50490260 38.51803280 38.53116300 38.54429317 38.55742333 38.57055347 38.58368358 38.59681368 38.60994375 38.62307380 38.63620382 38.64933381 38.66246377 38.67559371 38.68872361 38.70185348 38.71498331 38.72811311 38.74124287 38.75437259 38.76750228 38.78063192 38.79376152 38.80689107 38.82002058 38.83315004 38.84627945 38.85940882 38.87253813 38.88566739 38.89879660 38.91192575 38.92505485 38.93818388 38.95131286 38.96444178 38.97757063 38.99069943 39.00382815 39.01695681 39.03008541 39.04321393 39.05634239 39.06947077 39.08259908 39.09572731 39.10885547 39.12198355 39.13511156 39.14823948 39.16136732 39.17449508 39.18762276 39.20075034 39.21387785 39.22700526 39.24013259 39.25325982 39.26638696 39.27951401 39.29264096 39.30576782 39.31889458 39.33202124 39.34514780 39.35827425 39.37140060 39.38452685 39.39765300 39.41077903 39.42390496 39.43703077 39.45015648 39.46328207 39.47640754 39.48953290 39.50265815 39.51578327 39.52890828 39.54203316 39.55515792 39.56828256 39.58140707 39.59453146 39.60765572 39.62077984 39.63390384 39.64702770 39.66015143 39.67327503 39.68639849 39.69952181 39.71264499 39.72576804 39.73889094 39.75201369 39.76513630 39.77825877 39.79138109 39.80450326 39.81762528 39.83074715 39.84386886 39.85699042 39.87011183 39.88323308 39.89635417 39.90947510 39.92259587 39.93571647 39.94883692 39.96195719 39.97507731 39.98819725 40.00131702 40.01443663 40.02755606 40.04067531</listPositions>
				</positions>
				<positions axis="Omega" unit="deg">
					<commonPosition>19.1000</commonPosition>
				</positions>
				<positions axis="Z" unit="mm">
					<commonPosition>4.759</commonPosition>
				</positions>
				<commonCountingTime unit="seconds">16.946</commonCountingTime>
				<intensities unit="counts">106 135 148 129 175 182 178 228 240 247 263 267 274 271 306 289 301 273 325 290 306 291 278 314 319 287 299 313 300 325 327 336 332 287 325 352 322 307 293 315 302 332 273 292 294 301 322 320 251 326 327 316 303 291 327 321 322 324 296 318 284 332 307 324 289 296 310 301 364 355 327 306 313 347 348 345 352 339 343 360 359 373 394 361 422 413 425 507 532 595 677 748 768 814 864 915 921 894 952 825 865 795 739 783 759 750 697 758 749 750 672 703 739 772 782 825 793 791 801 762 735 704 752 752 711 612 612 574 525 568 526 506 477 455 408 410 408 344 379 389 362 342 388 376 372 331 335 327 340 293 327 360 311 324 322 330 358 327 324 324 291 334 304 313 311 325 346 282 298 294 295 324 312 307 291 318 281 331 284 311 342 282 289 299 315 297 307 296 272 262 320 305 311 274 271 297 307 290 309 298 316 277 311 285 317 308 286 307 284 335 293 290 254 300 309 271 295 280 274 268 293 275 286 297 260 243 250 293 279 264 296 281 292 255 257 272 282 266 233 268 228 214 245 203 232 208 246 227 218 205 192 188 209 158 146</intensities>
			</dataPoints>
			<nonAmbientPoints type="Temperature" unit="K">
				<measurementTimes unit="seconds">0</measurementTimes>
				<nonAmbientValues>294</nonAmbientValues>
			</nonAmbientPoints>
		</scan>
	</xrdMeasurement>
</xrdMeasurements>