File: SampleData/XRDDataKlarissa/53_47 at 25C.csv
[Measurement conditions]
Sample identification,
Comment - 1,"Configuration=TTK 450 + LNC, Owner=User-1, Creation date=7/12/2013 11:44:08 AM"
Comment - 2,"Goniometer=Theta/Theta; Minimum step size 2Theta:0.0001; Minimum step size Omega:0.0001"
Comment - 3,"Sample stage=AP TTK-450 with z-axis + LNC; Minimum step size Z:0.001"
Comment - 4,"Diffractometer system=EMPYREAN"
Comment - 5,"Measurement program=C:\PANalytical\Data Collector\Programs\BB\PI Ceramic\Single Scan.xrdmp, Identifier={41AC5C24-3E75-4249-BF39-599419EEFDC7}"
Comment - 6,"Height control correction model name=AP TTK-450 + Cu/Ni holder (air)"
Anode material,Cu
K-Alpha1 wavelength,1.5405980
K-Alpha2 wavelength,1.5444260
Ratio K-Alpha2/K-Alpha1,0.500
Divergence slit,Fixed,0.25
Monochromator used,YES
Generator voltage, 45
Tube current, 40
File date and time,05/Dec/2016 16:20
Unit cell,
h k l, 0 0 0
Temperature [K],291
Scan axis,Gonio
Scan range,14.999899997,60.010508423
Scan step size,0.0262606
No. of points, 1714
Scan type,CONTINUOUS
Z,7.729
Time per step,46.665
[Scan points]
Angle,Intensity
15.013030280,905.0
15.065551410,886.0
15.118072540,1014.0
15.170593670,988.0
15.223114800,964.0
15.275635930,1000.0
15.328157060,922.0
15.380678190,975.0
15.433199320,959.0
15.485720450,913.0
15.538241580,930.0
15.590762710,980.0
15.643283840,928.0
15.695804970,901.0
15.748326100,945.0
15.800847230,975.0
15.853368360,936.0
15.905889490,903.0
15.958410620,941.0
16.010931750,930.0
16.063452880,932.0
16.115974010,988.0
16.168495140,898.0
16.221016270,888.0
16.273537400,1005.0
16.326058530,935.0
16.378579660,910.0
16.431100790,912.0
16.483621920,968.0
16.536143051,933.0
16.588664181,987.0
16.641185311,852.0
16.693706441,921.0
16.746227571,951.0
16.798748701,938.0
16.851269831,968.0
16.903790961,968.0
16.956312091,913.0
17.008833221,904.0
17.061354351,916.0
17.113875481,928.0
17.166396611,913.0
17.218917741,952.0
17.271438871,880.0
17.323960001,914.0
17.376481131,895.0
17.429002261,857.0
17.481523391,938.0
17.534044521,915.0
17.586565651,870.0
17.639086781,812.0
17.691607911,891.0
17.744129041,891.0
17.796650171,944.0
17.849171301,843.0
17.901692431,937.0
17.954213561,890.0
18.006734691,883.0
18.059255821,910.0
18.111776951,894.0
18.164298081,864.0
18.216819211,833.0
18.269340341,955.0
18.321861471,872.0
18.374382601,887.0
18.426903731,810.0
18.479424861,847.0
18.531945991,800.0
18.584467121,820.0
18.636988251,849.0
18.689509381,811.0
18.742030511,833.0
18.794551641,857.0
18.847072771,848.0
18.899593901,857.0
18.952115031,864.0
19.004636161,805.0
19.057157291,798.0
19.109678421,876.0
19.162199551,835.0
19.214720681,854.0
19.267241811,918.0
19.319762941,851.0
19.372284071,804.0
19.424805201,895.0
19.477326331,828.0
19.529847462,821.0
19.582368592,808.0
19.634889722,813.0
19.687410852,870.0
19.739931982,848.0
19.792453112,841.0
19.844974242,777.0
19.897495372,812.0
19.950016502,867.0
20.002537632,839.0
20.055058762,830.0
20.107579892,792.0
20.160101022,815.0
20.212622152,833.0
20.265143282,836.0
20.317664412,834.0
20.370185542,890.0
20.422706672,795.0
20.475227802,833.0
20.527748932,866.0
20.580270062,837.0
20.632791192,891.0
20.685312322,813.0
20.737833452,791.0
20.790354582,819.0
20.842875712,828.0
20.895396842,815.0
20.947917972,803.0
21.000439102,878.0
21.052960232,834.0
21.105481362,846.0
21.158002492,868.0
21.210523622,904.0
21.263044752,942.0
21.315565882,1010.0
21.368087012,1255.0
21.420608142,1847.0
21.473129272,2505.0
21.525650402,2278.0
21.578171532,1835.0
21.630692662,1528.0
21.683213792,1512.0
21.735734922,1475.0
21.788256052,1479.0
21.840777182,1669.0
21.893298312,2036.0
21.945819442,2504.0
21.998340572,2816.0
22.050861702,1982.0
22.103382832,1158.0
22.155903962,863.0
22.208425092,815.0
22.260946222,867.0
22.313467352,834.0
22.365988482,755.0
22.418509612,821.0
22.471030742,847.0
22.523551873,803.0
22.576073003,746.0
22.628594133,775.0
22.681115263,741.0
22.733636393,815.0
22.786157523,772.0
22.838678653,802.0
22.891199783,795.0
22.943720913,778.0
22.996242043,715.0
23.048763173,779.0
23.101284303,745.0
23.153805433,723.0
23.206326563,729.0
23.258847693,713.0
23.311368823,788.0
23.363889953,743.0
23.416411083,730.0
23.468932213,770.0
23.521453343,777.0
23.573974473,783.0
23.626495603,737.0
23.679016733,748.0
23.731537863,741.0
23.784058993,721.0
23.836580123,753.0
23.889101253,765.0
23.941622383,706.0
23.994143513,765.0
24.046664643,716.0
24.099185773,744.0
24.151706903,726.0
24.204228033,745.0
24.256749163,735.0
24.309270293,758.0
24.361791423,682.0
24.414312553,729.0
24.466833683,695.0
24.519354813,760.0
24.571875943,740.0
24.624397073,719.0
24.676918203,749.0
24.729439333,692.0
24.781960463,743.0
24.834481593,702.0
24.887002723,695.0
24.939523853,744.0
24.992044983,752.0
25.044566113,757.0
25.097087243,779.0
25.149608373,699.0
25.202129503,725.0
25.254650633,683.0
25.307171763,721.0
25.359692893,735.0
25.412214023,724.0
25.464735153,767.0
25.517256284,726.0
25.569777414,774.0
25.622298544,769.0
25.674819674,732.0
25.727340804,709.0
25.779861934,760.0
25.832383064,731.0
25.884904194,669.0
25.937425324,679.0
25.989946454,745.0
26.042467584,732.0
26.094988714,733.0
26.147509844,742.0
26.200030974,693.0
26.252552104,735.0
26.305073234,704.0
26.357594364,688.0
26.410115494,695.0
26.462636624,716.0
26.515157754,705.0
26.567678884,715.0
26.620200014,641.0
26.672721144,759.0
26.725242274,682.0
26.777763404,709.0
26.830284534,732.0
26.882805664,746.0
26.935326794,707.0
26.987847924,713.0
27.040369054,684.0
27.092890184,727.0
27.145411314,774.0
27.197932444,719.0
27.250453574,685.0
27.302974704,679.0
27.355495834,702.0
27.408016964,721.0
27.460538094,726.0
27.513059224,744.0
27.565580354,706.0
27.618101484,706.0
27.670622614,740.0
27.723143744,723.0
27.775664874,743.0
27.828186004,739.0
27.880707134,725.0
27.933228264,721.0
27.985749394,706.0
28.038270524,701.0
28.090791654,731.0
28.143312784,707.0
28.195833914,756.0
28.248355044,681.0
28.300876174,768.0
28.353397304,651.0
28.405918434,684.0
28.458439564,735.0
28.510960695,702.0
28.563481825,685.0
28.616002955,706.0
28.668524085,676.0
28.721045215,711.0
28.773566345,725.0
28.826087475,665.0
28.878608605,703.0
28.931129735,774.0
28.983650865,690.0
29.036171995,706.0
29.088693125,721.0
29.141214255,689.0
29.193735385,638.0
29.246256515,699.0
29.298777645,667.0
29.351298775,645.0
29.403819905,676.0
29.456341035,701.0
29.508862165,750.0
29.561383295,723.0
29.613904425,697.0
29.666425555,697.0
29.718946685,743.0
29.771467815,712.0
29.823988945,800.0
29.876510075,708.0
29.929031205,777.0
29.981552335,803.0
30.034073465,758.0
30.086594595,827.0
30.139115725,804.0
30.191636855,843.0
30.244157985,827.0
30.296679115,807.0
30.349200245,838.0
30.401721375,834.0
30.454242505,832.0
30.506763635,916.0
30.559284765,890.0
30.611805895,1046.0
30.664327025,1209.0
30.716848155,1613.0
30.769369285,2729.0
30.821890415,5308.0
30.874411545,9692.0
30.926932675,12313.0
30.979453805,12251.0
31.031974935,10157.0
31.084496065,8030.0
31.137017195,6116.0
31.189538325,5544.0
31.242059455,6049.0
31.294580585,7030.0
31.347101715,4914.0
31.399622845,3030.0
31.452143975,1453.0
31.504665105,1079.0
31.557186236,877.0
31.609707366,859.0
31.662228496,793.0
31.714749626,794.0
31.767270756,768.0
31.819791886,760.0
31.872313016,738.0
31.924834146,729.0
31.977355276,712.0
32.029876406,718.0
32.082397536,699.0
32.134918666,693.0
32.187439796,692.0
32.239960926,681.0
32.292482056,705.0
32.345003186,690.0
32.397524316,718.0
32.450045446,656.0
32.502566576,711.0
32.555087706,698.0
32.607608836,679.0
32.660129966,698.0
32.712651096,667.0
32.765172226,691.0
32.817693356,699.0
32.870214486,706.0
32.922735616,714.0
32.975256746,672.0
33.027777876,641.0
33.080299006,627.0
33.132820136,701.0
33.185341266,651.0
33.237862396,664.0
33.290383526,664.0
33.342904656,683.0
33.395425786,665.0
33.447946916,632.0
33.500468046,670.0
33.552989176,662.0
33.605510306,655.0
33.658031436,690.0
33.710552566,688.0
33.763073696,659.0
33.815594826,681.0
33.868115956,623.0
33.920637086,666.0
33.973158216,674.0
34.025679346,670.0
34.078200476,686.0
34.130721606,635.0
34.183242736,660.0
34.235763866,671.0
34.288284996,684.0
34.340806126,584.0
34.393327256,701.0
34.445848386,646.0
34.498369516,635.0
34.550890647,655.0
34.603411777,679.0
34.655932907,610.0
34.708454037,630.0
34.760975167,651.0
34.813496297,679.0
34.866017427,591.0
34.918538557,629.0
34.971059687,655.0
35.023580817,653.0
35.076101947,584.0
35.128623077,618.0
35.181144207,657.0
35.233665337,632.0
35.286186467,608.0
35.338707597,695.0
35.391228727,678.0
35.443749857,610.0
35.496270987,591.0
35.548792117,610.0
35.601313247,634.0
35.653834377,636.0
35.706355507,596.0
35.758876637,673.0
35.811397767,668.0
35.863918897,578.0
35.916440027,613.0
35.968961157,633.0
36.021482287,585.0
36.074003417,593.0
36.126524547,609.0
36.179045677,621.0
36.231566807,597.0
36.284087937,616.0
36.336609067,618.0
36.389130197,589.0
36.441651327,598.0
36.494172457,536.0
36.546693587,607.0
36.599214717,631.0
36.651735847,646.0
36.704256977,598.0
36.756778107,607.0
36.809299237,681.0
36.861820367,619.0
36.914341497,635.0
36.966862627,642.0
37.019383757,657.0
37.071904887,668.0
37.124426017,662.0
37.176947147,617.0
37.229468277,612.0
37.281989407,621.0
37.334510537,640.0
37.387031667,644.0
37.439552797,598.0
37.492073927,652.0
37.544595058,656.0
37.597116188,631.0
37.649637318,608.0
37.702158448,579.0
37.754679578,616.0
37.807200708,648.0
37.859721838,631.0
37.912242968,692.0
37.964764098,737.0
38.017285228,827.0
38.069806358,1004.0
38.122327488,1396.0
38.174848618,1964.0
38.227369748,2917.0
38.279890878,3637.0
38.332412008,3550.0
38.384933138,2679.0
38.437454268,1853.0
38.489975398,1179.0
38.542496528,808.0
38.595017658,679.0
38.647538788,693.0
38.700059918,637.0
38.752581048,668.0
38.805102178,674.0
38.857623308,558.0
38.910144438,611.0
38.962665568,587.0
39.015186698,625.0
39.067707828,551.0
39.120228958,622.0
39.172750088,595.0
39.225271218,638.0
39.277792348,669.0
39.330313478,614.0
39.382834608,611.0
39.435355738,635.0
39.487876868,576.0
39.540397998,638.0
39.592919128,629.0
39.645440258,567.0
39.697961388,584.0
39.750482518,563.0
39.803003648,584.0
39.855524778,614.0
39.908045908,574.0
39.960567038,593.0
40.013088168,565.0
40.065609298,611.0
40.118130428,587.0
40.170651558,593.0
40.223172688,595.0
40.275693818,606.0
40.328214948,563.0
40.380736078,627.0
40.433257208,602.0
40.485778338,628.0
40.538299469,586.0
40.590820599,592.0
40.643341729,627.0
40.695862859,544.0
40.748383989,505.0
40.800905119,576.0
40.853426249,560.0
40.905947379,553.0
40.958468509,553.0
41.010989639,558.0
41.063510769,575.0
41.116031899,519.0
41.168553029,625.0
41.221074159,591.0
41.273595289,575.0
41.326116419,571.0
41.378637549,620.0
41.431158679,572.0
41.483679809,588.0
41.536200939,571.0
41.588722069,613.0
41.641243199,624.0
41.693764329,620.0
41.746285459,605.0
41.798806589,590.0
41.851327719,544.0
41.903848849,596.0
41.956369979,544.0
42.008891109,542.0
42.061412239,570.0
42.113933369,602.0
42.166454499,558.0
42.218975629,575.0
42.271496759,549.0
42.324017889,640.0
42.376539019,567.0
42.429060149,537.0
42.481581279,610.0
42.534102409,595.0
42.586623539,631.0
42.639144669,585.0
42.691665799,602.0
42.744186929,580.0
42.796708059,593.0
42.849229189,597.0
42.901750319,631.0
42.954271449,640.0
43.006792579,639.0
43.059313709,568.0
43.111834839,615.0
43.164355969,628.0
43.216877099,600.0
43.269398229,637.0
43.321919359,634.0
43.374440489,643.0
43.426961619,631.0
43.479482749,613.0
43.532003880,719.0
43.584525010,868.0
43.637046140,1221.0
43.689567270,1551.0
43.742088400,1634.0
43.794609530,1651.0
43.847130660,1535.0
43.899651790,1413.0
43.952172920,1361.0
44.004694050,1258.0
44.057215180,1096.0
44.109736310,1093.0
44.162257440,990.0
44.214778570,893.0
44.267299700,921.0
44.319820830,912.0
44.372341960,901.0
44.424863090,937.0
44.477384220,956.0
44.529905350,1054.0
44.582426480,1226.0
44.634947610,1263.0
44.687468740,1466.0
44.739989870,1934.0
44.792511000,2449.0
44.845032130,3093.0
44.897553260,2485.0
44.950074390,1922.0
45.002595520,1520.0
45.055116650,872.0
45.107637780,726.0
45.160158910,621.0
45.212680040,634.0
45.265201170,587.0
45.317722300,592.0
45.370243430,585.0
45.422764560,575.0
45.475285690,608.0
45.527806820,568.0
45.580327950,618.0
45.632849080,608.0
45.685370210,580.0
45.737891340,574.0
45.790412470,575.0
45.842933600,598.0
45.895454730,625.0
45.947975860,599.0
46.000496990,533.0
46.053018120,562.0
46.105539250,595.0
46.158060380,592.0
46.210581510,615.0
46.263102640,637.0
46.315623770,576.0
46.368144900,572.0
46.420666030,583.0
46.473187160,605.0
46.525708291,579.0
46.578229421,517.0
46.630750551,566.0
46.683271681,604.0
46.735792811,584.0
46.788313941,547.0
46.840835071,570.0
46.893356201,540.0
46.945877331,554.0
46.998398461,613.0
47.050919591,540.0
47.103440721,609.0
47.155961851,568.0
47.208482981,552.0
47.261004111,537.0
47.313525241,511.0
47.366046371,553.0
47.418567501,529.0
47.471088631,575.0
47.523609761,592.0
47.576130891,635.0
47.628652021,545.0
47.681173151,557.0
47.733694281,608.0
47.786215411,603.0
47.838736541,587.0
47.891257671,608.0
47.943778801,578.0
47.996299931,586.0
48.048821061,563.0
48.101342191,550.0
48.153863321,559.0
48.206384451,584.0
48.258905581,517.0
48.311426711,561.0
48.363947841,557.0
48.416468971,582.0
48.468990101,577.0
48.521511231,606.0
48.574032361,579.0
48.626553491,609.0
48.679074621,537.0
48.731595751,557.0
48.784116881,607.0
48.836638011,571.0
48.889159141,578.0
48.941680271,608.0
48.994201401,578.0
49.046722531,614.0
49.099243661,639.0
49.151764791,625.0
49.204285921,588.0
49.256807051,645.0
49.309328181,730.0
49.361849311,1048.0
49.414370441,1216.0
49.466891571,1181.0
49.519412702,1218.0
49.571933832,1175.0
49.624454962,1059.0
49.676976092,976.0
49.729497222,876.0
49.782018352,857.0
49.834539482,823.0
49.887060612,721.0
49.939581742,847.0
49.992102872,883.0
50.044624002,902.0
50.097145132,980.0
50.149666262,976.0
50.202187392,1023.0
50.254708522,1154.0
50.307229652,1123.0
50.359750782,985.0
50.412271912,991.0
50.464793042,941.0
50.517314172,957.0
50.569835302,791.0
50.622356432,738.0
50.674877562,671.0
50.727398692,670.0
50.779919822,603.0
50.832440952,561.0
50.884962082,620.0
50.937483212,598.0
50.990004342,579.0
51.042525472,608.0
51.095046602,578.0
51.147567732,563.0
51.200088862,625.0
51.252609992,589.0
51.305131122,646.0
51.357652252,658.0
51.410173382,652.0
51.462694512,628.0
51.515215642,639.0
51.567736772,647.0
51.620257902,602.0
51.672779032,573.0
51.725300162,552.0
51.777821292,555.0
51.830342422,591.0
51.882863552,599.0
51.935384682,547.0
51.987905812,552.0
52.040426942,576.0
52.092948072,580.0
52.145469202,566.0
52.197990332,526.0
52.250511462,571.0
52.303032592,563.0
52.355553722,583.0
52.408074852,582.0
52.460595982,578.0
52.513117113,543.0
52.565638243,586.0
52.618159373,578.0
52.670680503,591.0
52.723201633,554.0
52.775722763,528.0
52.828243893,567.0
52.880765023,607.0
52.933286153,588.0
52.985807283,558.0
53.038328413,590.0
53.090849543,625.0
53.143370673,577.0
53.195891803,544.0
53.248412933,594.0
53.300934063,603.0
53.353455193,578.0
53.405976323,575.0
53.458497453,606.0
53.511018583,599.0
53.563539713,577.0
53.616060843,570.0
53.668581973,531.0
53.721103103,580.0
53.773624233,566.0
53.826145363,622.0
53.878666493,559.0
53.931187623,569.0
53.983708753,594.0
54.036229883,571.0
54.088751013,583.0
54.141272143,608.0
54.193793273,633.0
54.246314403,594.0
54.298835533,621.0
54.351356663,634.0
54.403877793,638.0
54.456398923,674.0
54.508920053,787.0
54.561441183,1020.0
54.613962313,1398.0
54.666483443,1699.0
54.719004573,1967.0
54.771525703,2179.0
54.824046833,2129.0
54.876567963,1989.0
54.929089093,1872.0
54.981610223,1635.0
55.034131353,1599.0
55.086652483,1512.0
55.139173613,1533.0
55.191694743,1574.0
55.244215873,1597.0
55.296737003,1884.0
55.349258133,2196.0
55.401779263,2676.0
55.454300393,3480.0
55.506821524,3942.0
55.559342654,2960.0
55.611863784,2267.0
55.664384914,2093.0
55.716906044,1402.0
55.769427174,826.0
55.821948304,740.0
55.874469434,732.0
55.926990564,681.0
55.979511694,599.0
56.032032824,565.0
56.084553954,592.0
56.137075084,579.0
56.189596214,597.0
56.242117344,590.0
56.294638474,571.0
56.347159604,636.0
56.399680734,582.0
56.452201864,609.0
56.504722994,580.0
56.557244124,585.0
56.609765254,570.0
56.662286384,575.0
56.714807514,585.0
56.767328644,555.0
56.819849774,580.0
56.872370904,515.0
56.924892034,544.0
56.977413164,590.0
57.029934294,578.0
57.082455424,519.0
57.134976554,570.0
57.187497684,564.0
57.240018814,558.0
57.292539944,558.0
57.345061074,568.0
57.397582204,559.0
57.450103334,539.0
57.502624464,531.0
57.555145594,586.0
57.607666724,522.0
57.660187854,556.0
57.712708984,538.0
57.765230114,573.0
57.817751244,561.0
57.870272374,545.0
57.922793504,506.0
57.975314634,537.0
58.027835764,566.0
58.080356894,564.0
58.132878024,570.0
58.185399154,519.0
58.237920284,575.0
58.290441414,503.0
58.342962544,588.0
58.395483674,579.0
58.448004804,533.0
58.500525935,537.0
58.553047065,550.0
58.605568195,532.0
58.658089325,551.0
58.710610455,574.0
58.763131585,520.0
58.815652715,561.0
58.868173845,543.0
58.920694975,557.0
58.973216105,534.0
59.025737235,516.0
59.078258365,544.0
59.130779495,546.0
59.183300625,489.0
59.235821755,524.0
59.288342885,573.0
59.340864015,565.0
59.393385145,583.0
59.445906275,541.0
59.498427405,558.0
59.550948535,560.0
59.603469665,559.0
59.655990795,531.0
59.708511925,553.0
59.761033055,545.0
59.813554185,556.0
59.866075315,561.0
59.918596445,528.0
59.971117575,472.0
59.997378140,559.0